<?xml version="1.0"?>
<robot xmlns:xacro="http://www.ros.org/wiki/xacro">

  <xacro:include filename="inertial_macros.xacro" />
  <xacro:include filename="colours.xacro" />

  <!-- ====================== Constants ======================== -->
  <xacro:property name="wheel_from_center" value="0.2"/>

  <!-- ====================== Links ======================== -->
  <!-- Base Link -->
  <link name="base_link">

  </link>

  <!-- Chassis -->
  <link name="chassis">
    <visual>
      <!-- shift box forward so chassis link origin is centered at back bottom -->
      <origin xyz="0.375 0 0.075" />
      <geometry>
        <box size="0.75 0.3 0.15" />
      </geometry>
      <material name="white" />
    </visual>
    <!-- <collision>
        <origin xyz="0.15 0 0.075" />
        <geometry>
          <box size="0.3 0.3 0.15" />
        </geometry>
      </collision>
      <xacro:inertial_box mass="0.5" x="0.3" y="0.3" z="0.15">
        <origin xyz="0.15 0 0.075" rpy="0 0 0" />
      </xacro:inertial_box> -->
  </link>

  <gazebo reference="chassis">
    <material>Gazebo/White</material>
  </gazebo>

  <!-- Back Left Wheel -->
  <link name="left_back_wheel">
    <visual>
      <geometry>
        <cylinder radius="0.075" length="0.04" />
      </geometry>
      <material name="blue" />
    </visual>
    <!-- <collision>
      <geometry>
        <cylinder radius="0.05" length="0.04" />
      </geometry>
    </collision>
    <xacro:inertial_cylinder mass="0.1" length="0.04" radius="0.05">
      <origin xyz="0 0 0" rpy="0 0 0" />
    </xacro:inertial_cylinder> -->
  </link>

  <!-- Front Left Wheel -->
  <link name="left_front_wheel">
    <visual>
      <geometry>
        <cylinder radius="0.075" length="0.04" />
      </geometry>
      <material name="blue" />
    </visual>
    <!-- <collision>
      <geometry>
        <cylinder radius="0.05" length="0.04" />
      </geometry>
    </collision>
    <xacro:inertial_cylinder mass="0.1" length="0.04" radius="0.05">
      <origin xyz="0 0 0" rpy="0 0 0" />
    </xacro:inertial_cylinder> -->
  </link>

  <!-- Back Right Wheel -->
  <link name="right_back_wheel">
    <visual>
      <geometry>
        <cylinder radius="0.075" length="0.04" />
      </geometry>
      <material name="blue" />
    </visual>
    <!-- <collision>
      <geometry>
        <cylinder radius="0.05" length="0.04" />
      </geometry>
    </collision>
    <xacro:inertial_cylinder mass="0.1" length="0.04" radius="0.05">
      <origin xyz="0 0 0" rpy="0 0 0" />
    </xacro:inertial_cylinder> -->
  </link>

  <!-- Front Right Wheel -->
  <link name="right_front_wheel">
    <visual>
      <geometry>
        <cylinder radius="0.075" length="0.04" />
      </geometry>
      <material name="blue" />
    </visual>
    <!-- <collision>
        <geometry>
          <cylinder radius="0.05" length="0.04" />
        </geometry>
      </collision>
      <xacro:inertial_cylinder mass="0.1" length="0.04" radius="0.05">
        <origin xyz="0 0 0" rpy="0 0 0" />
      </xacro:inertial_cylinder> -->
  </link>

  <!-- ====================== Joints ======================== -->
  <!-- Chassis Joint -->
  <joint name="chassis_joint" type="fixed">
    <parent link="base_link" />
    <child link="chassis" />

    <!-- separation distance between base_link (middle of chassis) and chassis origin -->
    <origin xyz="-0.375 0 0" />
  </joint>

  <!-- Back Left Wheel Joint -->
  <joint name="left_back_wheel_joint" type="continuous">
    <parent link="base_link" />
    <child link="left_back_wheel" />

    <!-- transform from parent link to child link -->
    <!-- joint is located at origin of child link -->
    <origin xyz="-${wheel_from_center} 0.175 0" rpy="-${pi/2} 0 0" />

    <!-- axis of rotation; takes normalized vector of direction to rotate around -->
    <axis xyz="0 0 1" />
  </joint>

  <!-- Front Left Wheel Joint -->
  <joint name="left_front_wheel_joint" type="continuous">
    <parent link="base_link" />
    <child link="left_front_wheel" />

    <!-- transform from parent link to child link -->
    <!-- joint is located at origin of child link -->
    <origin xyz="${wheel_from_center} 0.175 0" rpy="-${pi/2} 0 0" />

    <!-- axis of rotation; takes normalized vector of direction to rotate around -->
    <axis xyz="0 0 1" />
  </joint>

  <!-- Back Right Wheel Joint -->
  <joint name="right_back_wheel_joint" type="continuous">
    <parent link="base_link" />
    <child link="right_back_wheel" />
    <origin xyz="-${wheel_from_center} -0.175 0" rpy="${pi/2} 0 0" />
    <axis xyz="0 0 -1" />
  </joint>

  <!-- Front Right Wheel Joint -->
  <joint name="right_front_wheel_joint" type="continuous">
    <parent link="base_link" />
    <child link="right_front_wheel" />

    <!-- transform from parent link to child link -->
    <!-- joint is located at origin of child link -->
    <origin xyz="${wheel_from_center} -0.175 0" rpy="-${pi/2} 0 0" />

    <!-- axis of rotation; takes normalized vector of direction to rotate around -->
    <axis xyz="0 0 -1" />
  </joint>


  <!-- Caster Wheel -->
  <!-- <joint name="caster_wheel_joint" type="fixed">
    <parent link="chassis" />
    <child link="caster_wheel" />
    <origin xyz="0.24 0 0" />
  </joint> -->

  <!-- <link name="caster_wheel">
    <visual>
      <geometry>
        <sphere radius="0.05" />
      </geometry>
      <material name="black" />
    </visual>
    <collision>
      <geometry>
        <sphere radius="0.05" />
      </geometry>
    </collision>
    <xacro:inertial_sphere mass="0.1" radius="0.05">
      <origin xyz="0 0 0" rpy="0 0 0" />
    </xacro:inertial_sphere>
  </link> -->
  <!-- 
  <gazebo reference="caster_wheel">
    <material>Gazebo/Black</material>
    <mu1 value="0.001"/>
    <mu2 value="0.001"/>
  </gazebo> -->

</robot>